Workbook

Sheet España
A1: País | B1: Año | C1: PIB_per_capita_€ | D1: Inflación_% | E1: Desempleo_% | F1: Crecimiento_PIB_%
A2: España | B2: 2019 | C2: 39564.14 | D2: 5.8 | E2: 16.32 | F2: 0.46
A3: España | B3: 2020 | C3: 38385.14 | D3: 6.54 | E3: 11.59 | F3: -7.77
A4: España | B4: 2021 | C4: 49929.16 | D4: -0.15 | E4: 15.31 | F4: 4.17
A5: España | B5: 2022 | C5: 40325.34 | D5: 8.06 | E5: 11.97 | F5: 1.28
A6: España | B6: 2023 | C6: 58328.86 | D6: 6.58 | E6: 17.77 | F6: -1.8

Sheet Francia
A1: País | B1: Año | C1: PIB_per_capita_€ | D1: Inflación_% | E1: Desempleo_% | F1: Crecimiento_PIB_%
A2: Francia | B2: 2019 | C2: 47563.62 | D2: 0.67 | E2: 11.61 | F2: -5.81
A3: Francia | B3: 2020 | C3: 56511.45 | D3: 0.36 | E3: 17.11 | F3: -6.41
A4: Francia | B4: 2021 | C4: 26386.02 | D4: 0.25 | E4: 16.75 | F4: 2.42
A5: Francia | B5: 2022 | C5: 53064.37 | D5: 6.56 | E5: 13.43 | F5: -3.19
A6: Francia | B6: 2023 | C6: 25061.87 | D6: 7.45 | E6: 11.21 | F6: -7.1

Sheet Alemania
A1: País | B1: Año | C1: PIB_per_capita_€ | D1: Inflación_% | E1: Desempleo_% | F1: Crecimiento_PIB_%
A2: Alemania | B2: 2019 | C2: 56058.77 | D2: 0.57 | E2: 11.64 | F2: -4.29
A3: Alemania | B3: 2020 | C3: 53796.31 | D3: 9.45 | E3: 15.09 | F3: -6.15
A4: Alemania | B4: 2021 | C4: 43047.33 | D4: 2.02 | E4: 6.23 | F4: -6.79
A5: Alemania | B5: 2022 | C5: 51480.44 | D5: 0.41 | E5: 16.5 | F5: -1.21
A6: Alemania | B6: 2023 | C6: 30357.03 | D6: 3.71 | E6: 3.5 | F6: 3.71

Sheet Italia
A1: País | B1: Año | C1: PIB_per_capita_€ | D1: Inflación_% | E1: Desempleo_% | F1: Crecimiento_PIB_%
A2: Italia | B2: 2019 | C2: 58210.25 | D2: 7.03 | E2: 9.6 | F2: 1.16
A3: Italia | B3: 2020 | C3: 52220.95 | D3: 9.59 | E3: 16.26 | F3: 0.02
A4: Italia | B4: 2021 | C4: 28048.06 | D4: 2 | E4: 10.67 | F4: 4.99
A5: Italia | B5: 2022 | C5: 27340.35 | D5: 5 | E5: 11.49 | F5: 4.19
A6: Italia | B6: 2023 | C6: 29902.32 | D6: 7.45 | E6: 13.28 | F6: -1.24

Sheet Portugal
A1: País | B1: Año | C1: PIB_per_capita_€ | D1: Inflación_% | E1: Desempleo_% | F1: Crecimiento_PIB_%
A2: Portugal | B2: 2019 | C2: 31813.17 | D2: 1.82 | E2: 12.57 | F2: 0.62
A3: Portugal | B3: 2020 | C3: 50619.34 | D3: 9.65 | E3: 6.78 | F3: 3.76
A4: Portugal | B4: 2021 | C4: 35978.78 | D4: 2.1 | E4: 4.99 | F4: -1.76
A5: Portugal | B5: 2022 | C5: 42802.04 | D5: -0.07 | E5: 10.04 | F5: -7.02
A6: Portugal | B6: 2023 | C6: 32187.79 | D6: 3.97 | E6: 3.41 | F6: 2.41

Sheet Grecia
A1: País | B1: Año | C1: PIB_per_capita_€ | D1: Inflación_% | E1: Desempleo_% | F1: Crecimiento_PIB_%
A2: Grecia | B2: 2019 | C2: 33716.56 | D2: 2.13 | E2: 14.31 | F2: 5.34
A3: Grecia | B3: 2020 | C3: 48110.36 | D3: 8.52 | E3: 11.49 | F3: 3.4
A4: Grecia | B4: 2021 | C4: 48800.67 | D4: 5.16 | E4: 8.16 | F4: -3.8
A5: Grecia | B5: 2022 | C5: 42934.75 | D5: 3.98 | E5: 14.36 | F5: 5.95
A6: Grecia | B6: 2023 | C6: 38404 | D6: 8.57 | E6: 12.99 | F6: 2.29

Sheet Países Bajos
A1: País | B1: Año | C1: PIB_per_capita_€ | D1: Inflación_% | E1: Desempleo_% | F1: Crecimiento_PIB_%
A2: Países Bajos | B2: 2019 | C2: 48265.4 | D2: 6.47 | E2: 11.41 | F2: -7.18
A3: Países Bajos | B3: 2020 | C3: 33188.99 | D3: 2.71 | E3: 5 | F3: -0.83
A4: Países Bajos | B4: 2021 | C4: 37404.2 | D4: 5.3 | E4: 10.77 | F4: -2.09
A5: Países Bajos | B5: 2022 | C5: 31514.55 | D5: 6.58 | E5: 11.02 | F5: -4.97
A6: Países Bajos | B6: 2023 | C6: 40302.55 | D6: 9.14 | E6: 15.27 | F6: -0.75

Sheet Suecia
A1: País | B1: Año | C1: PIB_per_capita_€ | D1: Inflación_% | E1: Desempleo_% | F1: Crecimiento_PIB_%
A2: Suecia | B2: 2019 | C2: 42634.04 | D2: 3.55 | E2: 16.13 | F2: 1.03
A3: Suecia | B3: 2020 | C3: 59833.03 | D3: 8.7 | E3: 9.47 | F3: -3.86
A4: Suecia | B4: 2021 | C4: 43260.41 | D4: 6.07 | E4: 10.95 | F4: 1.73
A5: Suecia | B5: 2022 | C5: 50017.43 | D5: 2.53 | E5: 8.75 | F5: -6.13
A6: Suecia | B6: 2023 | C6: 29420.06 | D6: 1.78 | E6: 11.18 | F6: -6.94

Sheet Polonia
A1: País | B1: Año | C1: PIB_per_capita_€ | D1: Inflación_% | E1: Desempleo_% | F1: Crecimiento_PIB_%
A2: Polonia | B2: 2019 | C2: 30669.03 | D2: -0.13 | E2: 6.01 | F2: 3.95
A3: Polonia | B3: 2020 | C3: 49873.54 | D3: 1.41 | E3: 16.1 | F3: -5.78
A4: Polonia | B4: 2021 | C4: 38214.89 | D4: -0.44 | E4: 15.67 | F4: 1.55
A5: Polonia | B5: 2022 | C5: 41651.9 | D5: 3.94 | E5: 7.38 | F5: 2.14
A6: Polonia | B6: 2023 | C6: 55333.15 | D6: 7.05 | E6: 10.75 | F6: -1.69

Sheet Irlanda
A1: País | B1: Año | C1: PIB_per_capita_€ | D1: Inflación_% | E1: Desempleo_% | F1: Crecimiento_PIB_%
A2: Irlanda | B2: 2019 | C2: 26936.62 | D2: 5.64 | E2: 6.06 | F2: -3.4
A3: Irlanda | B3: 2020 | C3: 31825.9 | D3: 3.33 | E3: 7.44 | F3: 2.49
A4: Irlanda | B4: 2021 | C4: 47988.58 | D4: 2.06 | E4: 10.41 | F4: 3.65
A5: Irlanda | B5: 2022 | C5: 57028.02 | D5: 4.38 | E5: 13.79 | F5: -6.42
A6: Irlanda | B6: 2023 | C6: 41998.02 | D6: -0.2 | E6: 5.63 | F6: 0.65

Sheet Principal
A1: INFORME MACROECONÓMICO EUROPEO — DATOS CONSOLIDADOS
A3: País | B3: Año | C3: PIB_per_capita_€ | D3: Inflación_% | E3: Desempleo_% | F3: Crecimiento_PIB_%
A4: Alemania | B4: 2019 | C4: 56058.77 | D4: 0.57 | E4: 11.64 | F4: -4.29
A5: Alemania | B5: 2020 | C5: 53796.31 | D5: 9.45 | E5: 15.09 | F5: -6.15
A6: Alemania | B6: 2021 | C6: 43047.33 | D6: 2.02 | E6: 6.23 | F6: -6.79
A7: Alemania | B7: 2022 | C7: 51480.44 | D7: 0.41 | E7: 16.5 | F7: -1.21
A8: Alemania | B8: 2023 | C8: 30357.03 | D8: 3.71 | E8: 3.5 | F8: 3.71
A9: España | B9: 2019 | C9: 39564.14 | D9: 5.8 | E9: 16.32 | F9: 0.46
A10: España | B10: 2020 | C10: 38385.14 | D10: 6.54 | E10: 11.59 | F10: -7.77
A11: España | B11: 2021 | C11: 49929.16 | D11: -0.15 | E11: 15.31 | F11: 4.17
A12: España | B12: 2022 | C12: 40325.34 | D12: 8.06 | E12: 11.97 | F12: 1.28
A13: España | B13: 2023 | C13: 58328.86 | D13: 6.58 | E13: 17.77 | F13: -1.8
A14: Francia | B14: 2019 | C14: 47563.62 | D14: 0.67 | E14: 11.61 | F14: -5.81
A15: Francia | B15: 2020 | C15: 56511.45 | D15: 0.36 | E15: 17.11 | F15: -6.41
... A53: Suecia | B53: 2023 | C53: 29420.06 | D53: 1.78 | E53: 11.18 | F53: -6.94
A56: ESTADÍSTICA DESCRIPTIVA — TOTALES
A57: Estadístico | B57: PIB_per_capita_€ | C57: Inflación_% | D57: Desempleo_% | E57: Crecimiento_PIB_%
A58: MEDIA | B58: 42166.191 | C58: 4.301 | D58: 11.3124 | E58: -1.0204
A59: MEDIANA | B59: 42316.03 | C59: 3.975 | D59: 11.45 | E59: -0.79
A60: DESV.TÍPICA | B60: 10077.684 | C60: 3.1126813 | D60: 3.8464888 | E60: 4.0932597
A61: MÍNIMO | B61: 25061.87 | C61: -0.44 | D61: 3.41 | E61: -7.77
A62: MÁXIMO | B62: 59833.03 | C62: 9.65 | D62: 17.77 | E62: 5.95
A63: CUENTA | B63: 50 | C63: 50 | D63: 50 | E63: 50
A64: VARIANZA | B64: 1.0155971e+08 | C64: 9.6887847 | D64: 14.795476 | E64: 16.754775
A67: ESTADÍSTICA POR PAÍS — PIB per cápita medio
A68: País | B68: Media PIB € | C68: Mediana PIB € | D68: Desv. Típica | E68: Mín PIB € | F68: Máx PIB €
A69: España | B69: 45306.528 | C69: 40325.34 | D69: 8611.6596 | E69: 38385.14 | F69: 58328.86
A70: Francia | B70: 41717.466 | C70: 47563.62 | D70: 14952.039 | E70: 25061.87 | F70: 56511.45
A71: Alemania | B71: 46947.976 | C71: 51480.44 | D71: 10499.095 | E71: 30357.03 | F71: 56058.77
A72: Italia | B72: 39144.386 | C72: 29902.32 | D72: 14852.468 | E72: 27340.35 | F72: 58210.25
A73: Portugal | B73: 38680.224 | C73: 35978.78 | D73: 8002.1526 | E73: 31813.17 | F73: 50619.34
A74: Grecia | B74: 42393.268 | C74: 42934.75 | D74: 6427.1429 | E74: 33716.56 | F74: 48800.67
A75: Países Bajos | B75: 38135.138 | C75: 37404.2 | D75: 6636.0892 | E75: 31514.55 | F75: 48265.4
A76: Suecia | B76: 45032.994 | C76: 43260.41 | D76: 11141.661 | E76: 29420.06 | F76: 59833.03
A77: Polonia | B77: 43148.502 | C77: 41651.9 | D77: 9695.4803 | E77: 30669.03 | F77: 55333.15
A78: Irlanda | B78: 41155.428 | C78: 41998.02 | D78: 12130.083 | E78: 26936.62 | F78: 57028.02
A81: FÓRMULAS CON REFERENCIAS ENTRE HOJAS (ejemplos)
A82: País | B82: Fórmula PROMEDIO PIB | C82: Fórmula MAX PIB | D82: Fórmula MIN PIB | E82: Fórmula CONTAR | F82: Fórmula DESVEST
A83: España | B83: =AVERAGE(España!C2:C6) | C83: =MAX(España!C2:C6) | D83: =MIN(España!C2:C6) | E83: =COUNT(España!C2:C6) | F83: =STDEV(España!C2:C6)
A84: Francia | B84: =AVERAGE(Francia!C2:C6) | C84: =MAX(Francia!C2:C6) | D84: =MIN(Francia!C2:C6) | E84: =COUNT(Francia!C2:C6) | F84: =STDEV(Francia!C2:C6)
...

Sheet Condicional
A1: FORMATO CONDICIONAL — Alertas Macroeconómicas
A3: País | B3: Año | C3: PIB_per_capita_€ | D3: Inflación_% | E3: Desempleo_% | F3: Crecimiento_PIB_%
A4: Alemania | B4: 2019 | C4: 56058.77 | D4: 0.57 | E4: 11.64 | F4: -4.29
A5: Alemania | B5: 2020 | C5: 53796.31 | D5: 9.45 | E5: 15.09 | F5: -6.15
A6: Alemania | B6: 2021 | C6: 43047.33 | D6: 2.02 | E6: 6.23 | F6: -6.79
A7: Alemania | B7: 2022 | C7: 51480.44 | D7: 0.41 | E7: 16.5 | F7: -1.21
A8: Alemania | B8: 2023 | C8: 30357.03 | D8: 3.71 | E8: 3.5 | F8: 3.71
A9: España | B9: 2019 | C9: 39564.14 | D9: 5.8 | E9: 16.32 | F9: 0.46
A10: España | B10: 2020 | C10: 38385.14 | D10: 6.54 | E10: 11.59 | F10: -7.77
A11: España | B11: 2021 | C11: 49929.16 | D11: -0.15 | E11: 15.31 | F11: 4.17
A12: España | B12: 2022 | C12: 40325.34 | D12: 8.06 | E12: 11.97 | F12: 1.28
A13: España | B13: 2023 | C13: 58328.86 | D13: 6.58 | E13: 17.77 | F13: -1.8
A14: Francia | B14: 2019 | C14: 47563.62 | D14: 0.67 | E14: 11.61 | F14: -5.81
A15: Francia | B15: 2020 | C15: 56511.45 | D15: 0.36 | E15: 17.11 | F15: -6.41
... A53: Suecia | B53: 2023 | C53: 29420.06 | D53: 1.78 | E53: 11.18 | F53: -6.94
A55: LEYENDA:
A56: ■ Inflación > 5%
A57: ■ Desempleo > 12%
A58: ■ Crecimiento negativo

Sheet Buscar
A1: BÚSQUEDA — Clasificación de Inflación de España (BUSCARV)
A3: País | B3: Año | C3: PIB_per_capita_€ | D3: Inflación_% | E3: Desempleo_% | F3: Crecimiento_PIB_% | G3: Clasificación_Inflación | H3: Tabla Clasificación
A4: Alemania | B4: 2019 | C4: 56058.77 | D4: 0.57 | E4: 11.64 | F4: -4.29 | G4: Inflación moderada | H4: Límite Inferior | I4: Clasificación
A5: Alemania | B5: 2020 | C5: 53796.31 | D5: 9.45 | E5: 15.09 | F5: -6.15 | G5: Alta inflación | H5: -100 | I5: Inflación moderada
A6: Alemania | B6: 2021 | C6: 43047.33 | D6: 2.02 | E6: 6.23 | F6: -6.79 | G6: Inflación controlada | H6: 2 | I6: Inflación controlada
A7: Alemania | B7: 2022 | C7: 51480.44 | D7: 0.41 | E7: 16.5 | F7: -1.21 | G7: Inflación moderada | H7: 5 | I7: Alta inflación
A8: Alemania | B8: 2023 | C8: 30357.03 | D8: 3.71 | E8: 3.5 | F8: 3.71 | G8: Inflación controlada
A9: España | B9: 2019 | C9: 39564.14 | D9: 5.8 | E9: 16.32 | F9: 0.46 | G9: Alta inflación
A10: España | B10: 2020 | C10: 38385.14 | D10: 6.54 | E10: 11.59 | F10: -7.77 | G10: Alta inflación
A11: España | B11: 2021 | C11: 49929.16 | D11: -0.15 | E11: 15.31 | F11: 4.17 | G11: Inflación moderada
A12: España | B12: 2022 | C12: 40325.34 | D12: 8.06 | E12: 11.97 | F12: 1.28 | G12: Alta inflación
A13: España | B13: 2023 | C13: 58328.86 | D13: 6.58 | E13: 17.77 | F13: -1.8 | G13: Alta inflación
A14: Francia | B14: 2019 | C14: 47563.62 | D14: 0.67 | E14: 11.61 | F14: -5.81 | G14: Inflación moderada
A15: Francia | B15: 2020 | C15: 56511.45 | D15: 0.36 | E15: 17.11 | F15: -6.41 | G15: Inflación moderada
A16: Francia | B16: 2021 | C16: 26386.02 | D16: 0.25 | E16: 16.75 | F16: 2.42 | G16: Inflación moderada
A17: Francia | B17: 2022 | C17: 53064.37 | D17: 6.56 | E17: 13.43 | F17: -3.19 | G17: Alta inflación
A18: Francia | B18: 2023 | C18: 25061.87 | D18: 7.45 | E18: 11.21 | F18: -7.1 | G18: Alta inflación
A19: Grecia | B19: 2019 | C19: 33716.56 | D19: 2.13 | E19: 14.31 | F19: 5.34 | G19: Inflación controlada
... A53: Suecia | B53: 2023 | C53: 29420.06 | D53: 1.78 | E53: 11.18 | F53: -6.94 | G53: Inflación moderada
A56: FÓRMULAS BUSCARV — Clasificación automática de inflación de España
A57: Año | B57: Inflación España | C57: Clasificación (BUSCARV)
A58: 2019 | B58: 5.8 | C58: =VLOOKUP(B58,$H$5:$I$7,2,TRUE)
A59: 2020 | B59: 6.54 | C59: =VLOOKUP(B59,$H$5:$I$7,2,TRUE)
A60: 2021 | B60: -0.15 | C60: =VLOOKUP(B60,$H$5:$I$7,2,TRUE)
A61: 2022 | B61: 8.06 | C61: =VLOOKUP(B61,$H$5:$I$7,2,TRUE)
A62: 2023 | B62: 6.58 | C62: =VLOOKUP(B62,$H$5:$I$7,2,TRUE)

Sheet Dashboard
A1: DASHBOARD MACROECONÓMICO EUROPEO
A2: Análisis comparativo de indicadores económicos (2019-2023) — Datos simulados
A35: País | B35: PIB Medio € | C35: Desempleo Medio % | D35: Inflación Media %
A36: España | B36: 45306.53 | C36: 14.59 | D36: 5.37
A37: Francia | B37: 41717.47 | C37: 14.02 | D37: 3.06
A38: Alemania | B38: 46947.98 | C38: 10.59 | D38: 3.23
A39: Italia | B39: 39144.39 | C39: 12.26 | D39: 6.21
A40: Portugal | B40: 38680.22 | C40: 7.56 | D40: 3.49
A41: Grecia | B41: 42393.27 | C41: 12.26 | D41: 5.67
A42: Países Bajos | B42: 38135.14 | C42: 10.69 | D42: 6.04
A43: Suecia | B43: 45032.99 | C43: 11.3 | D43: 4.53
A44: Polonia | B44: 43148.5 | C44: 11.18 | D44: 2.37
A45: Irlanda | B45: 41155.43 | C45: 8.67 | D45: 3.04
A48: Año | B48: España | C48: Francia | D48: Alemania | E48: Italia | F48: Portugal | G48: Grecia | H48: Países Bajos | I48: Suecia | J48: Polonia | K48: Irlanda
A49: 2019 | B49: 39564.14 | C49: 47563.62 | D49: 56058.77 | E49: 58210.25 | F49: 31813.17 | G49: 33716.56 | H49: 48265.4 | I49: 42634.04 | J49: 30669.03 | K49: 26936.62
A50: 2020 | B50: 38385.14 | C50: 56511.45 | D50: 53796.31 | E50: 52220.95 | F50: 50619.34 | G50: 48110.36 | H50: 33188.99 | I50: 59833.03 | J50: 49873.54 | K50: 31825.9
A51: 2021 | B51: 49929.16 | C51: 26386.02 | D51: 43047.33 | E51: 28048.06 | F51: 35978.78 | G51: 48800.67 | H51: 37404.2 | I51: 43260.41 | J51: 38214.89 | K51: 47988.58
A52: 2022 | B52: 40325.34 | C52: 53064.37 | D52: 51480.44 | E52: 27340.35 | F52: 42802.04 | G52: 42934.75 | H52: 31514.55 | I52: 50017.43 | J52: 41651.9 | K52: 57028.02
A53: 2023 | B53: 58328.86 | C53: 25061.87 | D53: 30357.03 | E53: 29902.32 | F53: 32187.79 | G53: 38404 | H53: 40302.55 | I53: 29420.06 | J53: 55333.15 | K53: 41998.02

Sheet Dinámicas1
A1: TABLA DINÁMICA — PIB medio por país
A3: País | B3: PIB Medio (€) | C3: Nº Registros
A4: España | B4: 45306.53 | C4: 5
A5: Francia | B5: 41717.47 | C5: 5
A6: Alemania | B6: 46947.98 | C6: 5
A7: Italia | B7: 39144.39 | C7: 5
A8: Portugal | B8: 38680.22 | C8: 5
A9: Grecia | B9: 42393.27 | C9: 5
A10: Países Bajos | B10: 38135.14 | C10: 5
A11: Suecia | B11: 45032.99 | C11: 5
A12: Polonia | B12: 43148.5 | C12: 5
A13: Irlanda | B13: 41155.43 | C13: 5
A14: TOTAL GENERAL | B14: 42166.19 | C14: 50

Sheet Dinámicas2
A1: TABLA DINÁMICA — Desempleo medio por país y año (con segmentación)
A3: País | B3: 2019 | C3: 2020 | D3: 2021 | E3: 2022 | F3: 2023 | G3: Promedio General
A4: España | B4: 16.32 | C4: 11.59 | D4: 15.31 | E4: 11.97 | F4: 17.77 | G4: 14.59
A5: Francia | B5: 11.61 | C5: 17.11 | D5: 16.75 | E5: 13.43 | F5: 11.21 | G5: 14.02
A6: Alemania | B6: 11.64 | C6: 15.09 | D6: 6.23 | E6: 16.5 | F6: 3.5 | G6: 10.59
A7: Italia | B7: 9.6 | C7: 16.26 | D7: 10.67 | E7: 11.49 | F7: 13.28 | G7: 12.26
A8: Portugal | B8: 12.57 | C8: 6.78 | D8: 4.99 | E8: 10.04 | F8: 3.41 | G8: 7.56
A9: Grecia | B9: 14.31 | C9: 11.49 | D9: 8.16 | E9: 14.36 | F9: 12.99 | G9: 12.26
A10: Países Bajos | B10: 11.41 | C10: 5 | D10: 10.77 | E10: 11.02 | F10: 15.27 | G10: 10.69
A11: Suecia | B11: 16.13 | C11: 9.47 | D11: 10.95 | E11: 8.75 | F11: 11.18 | G11: 11.3
A12: Polonia | B12: 6.01 | C12: 16.1 | D12: 15.67 | E12: 7.38 | F12: 10.75 | G12: 11.18
A13: Irlanda | B13: 6.06 | C13: 7.44 | D13: 10.41 | E13: 13.79 | F13: 5.63 | G13: 8.67
A16: NOTA: En Excel, insertar Segmentación de datos (Slicer) desde Insertar → Segmentación de datos para filtrar por año interactivamente.

Sheet Pearson
A1: ANÁLISIS DE CORRELACIÓN DE PEARSON — España (2019-2023)
A3: Variable X: Desempleo_% de España
A4: Variable Y: PIB_per_capita_€ de España
A6: Año | B6: Desempleo_% (X) | C6: PIB_per_capita_€ (Y) | D6: X² | E6: Y² | F6: X·Y
A7: 2019 | B7: 16.32 | C7: 39564.14 | D7: 266.3424 | E7: 1.5653212e+09 | F7: 645686.76
A8: 2020 | B8: 11.59 | C8: 38385.14 | D8: 134.3281 | E8: 1.473419e+09 | F8: 444883.77
A9: 2021 | B9: 15.31 | C9: 49929.16 | D9: 234.3961 | E9: 2.492921e+09 | F9: 764415.44
A10: 2022 | B10: 11.97 | C10: 40325.34 | D10: 143.2809 | E10: 1.626133e+09 | F10: 482694.32
A11: 2023 | B11: 17.77 | C11: 58328.86 | D11: 315.7729 | E11: 3.4022559e+09 | F11: 1036503.8
A12: SUMATORIO | B12: 72.96 | C12: 226532.64 | D12: 1094.1204 | E12: 1.056005e+10 | F12: 3374184.1
A14: RESULTADOS DEL ANÁLISIS
A15: Parámetro | B15: Valor
A16: n (observaciones) | B16: 5
A17: Σx | B17: 72.96
A18: Σy | B18: 226532.64
A19: Σxy | B19: 3374184.1
A20: Σx² | B20: 1094.1204
A21: Σy² | B21: 1.056005e+10
A22: Numerador (nΣxy − ΣxΣy) | B22: 343099.28
A23: Denominador √[(nΣx²−(Σx)²)(nΣy²−(Σy)²)] | B23: 467638.33
A24: Coeficiente de Pearson (r) | B24: 0.733685
A25: r² | B25: 0.538294
A27: INTERPRETACIÓN: La correlación entre el desempleo y el PIB per cápita de España es fuerte y positiva (directa) (r = 0.7337).
A28: El coeficiente de determinación r² = 0.5383 indica que el 53.83% de la variabilidad del PIB se explica por el desempleo.
A30: Fórmula Excel equivalente:
A31: =PEARSON(B7:B11,C7:C11)
